const x = 5

try{
    x = 10
} catch(err){
    console.log(`Erro : ${err}`)
}